
export class ErrorAnalyzer {
  async testNetworkErrorRecovery(): Promise<any> {
    console.log('🔍 ErrorAnalyzer: Testing network error recovery...');
    
    try {
      // Simulate network error scenarios
      const testScenarios = [
        {
          name: 'Connection timeout simulation',
          test: () => this.simulateConnectionTimeout()
        },
        {
          name: 'Rate limiting simulation',
          test: () => this.simulateRateLimit()
        },
        {
          name: 'Server error simulation',
          test: () => this.simulateServerError()
        }
      ];

      const results = [];

      for (const scenario of testScenarios) {
        try {
          const result = await scenario.test();
          results.push({
            scenario: scenario.name,
            status: 'passed',
            result
          });
        } catch (error) {
          results.push({
            scenario: scenario.name,
            status: 'handled',
            error: error instanceof Error ? error.message : 'Unknown error'
          });
        }
      }

      return {
        success: true,
        message: 'Network error recovery testing completed',
        details: results
      };
    } catch (error) {
      throw new Error(`Network error recovery testing failed: ${error instanceof Error ? error.message : 'Unknown error'}`);
    }
  }

  async testDataValidationErrors(): Promise<any> {
    console.log('🔍 ErrorAnalyzer: Testing data validation error handling...');
    
    try {
      const validationTests = [
        {
          name: 'Invalid player data',
          test: () => this.validateInvalidPlayerData()
        },
        {
          name: 'Invalid fixture data',
          test: () => this.validateInvalidFixtureData()
        },
        {
          name: 'Invalid team data',
          test: () => this.validateInvalidTeamData()
        }
      ];

      const results = [];

      for (const test of validationTests) {
        try {
          const result = await test.test();
          results.push({
            test: test.name,
            status: result.isValid ? 'passed' : 'validation_error',
            errors: result.errors || []
          });
        } catch (error) {
          results.push({
            test: test.name,
            status: 'error',
            error: error instanceof Error ? error.message : 'Unknown error'
          });
        }
      }

      return {
        success: true,
        message: 'Data validation error handling testing completed',
        details: results
      };
    } catch (error) {
      throw new Error(`Data validation error testing failed: ${error instanceof Error ? error.message : 'Unknown error'}`);
    }
  }

  async testConcurrentOperations(): Promise<any> {
    console.log('🔍 ErrorAnalyzer: Testing concurrent operations handling...');
    
    try {
      // Simulate concurrent operations
      const concurrentTasks = [
        () => this.simulateGoalAssignment(),
        () => this.simulateCardCreation(),
        () => this.simulateScoreUpdate(),
        () => this.simulatePlayerTimeUpdate()
      ];

      // Run tasks concurrently
      const startTime = Date.now();
      const results = await Promise.allSettled(
        concurrentTasks.map(task => task())
      );
      const duration = Date.now() - startTime;

      const successful = results.filter(r => r.status === 'fulfilled').length;
      const failed = results.filter(r => r.status === 'rejected').length;

      return {
        success: true,
        message: `Concurrent operations test completed: ${successful} successful, ${failed} failed`,
        details: {
          totalTasks: concurrentTasks.length,
          successful,
          failed,
          duration,
          results: results.map((r, i) => ({
            task: i,
            status: r.status,
            result: r.status === 'fulfilled' ? r.value : r.reason
          }))
        }
      };
    } catch (error) {
      throw new Error(`Concurrent operations testing failed: ${error instanceof Error ? error.message : 'Unknown error'}`);
    }
  }

  async testRecoveryMechanisms(): Promise<any> {
    console.log('🔍 ErrorAnalyzer: Testing recovery mechanisms...');
    
    try {
      const recoveryTests = [
        {
          name: 'State recovery after error',
          test: () => this.testStateRecovery()
        },
        {
          name: 'Data rollback capabilities',
          test: () => this.testDataRollback()
        },
        {
          name: 'Retry mechanism effectiveness',
          test: () => this.testRetryMechanism()
        }
      ];

      const results = [];

      for (const test of recoveryTests) {
        try {
          const result = await test.test();
          results.push({
            test: test.name,
            status: 'passed',
            result
          });
        } catch (error) {
          results.push({
            test: test.name,
            status: 'failed',
            error: error instanceof Error ? error.message : 'Unknown error'
          });
        }
      }

      return {
        success: true,
        message: 'Recovery mechanisms testing completed',
        details: results
      };
    } catch (error) {
      throw new Error(`Recovery mechanisms testing failed: ${error instanceof Error ? error.message : 'Unknown error'}`);
    }
  }

  // Helper methods for simulation
  private async simulateConnectionTimeout(): Promise<any> {
    return new Promise((resolve, reject) => {
      setTimeout(() => {
        reject(new Error('Connection timeout'));
      }, 100);
    });
  }

  private async simulateRateLimit(): Promise<any> {
    throw new Error('Rate limit exceeded');
  }

  private async simulateServerError(): Promise<any> {
    throw new Error('Internal server error');
  }

  private validateInvalidPlayerData(): any {
    const invalidPlayer = {
      name: '', // Invalid: empty name
      goals: -1, // Invalid: negative goals
      team_id: null // Invalid: missing team
    };

    const errors = [];
    
    if (!invalidPlayer.name || invalidPlayer.name.trim() === '') {
      errors.push('Player name is required');
    }
    
    if (invalidPlayer.goals < 0) {
      errors.push('Goals cannot be negative');
    }
    
    if (!invalidPlayer.team_id) {
      errors.push('Team ID is required');
    }

    return {
      isValid: errors.length === 0,
      errors
    };
  }

  private validateInvalidFixtureData(): any {
    const invalidFixture = {
      home_score: -1, // Invalid: negative score
      away_score: null, // Invalid: missing score
      home_team_id: '', // Invalid: empty team ID
      away_team_id: null // Invalid: missing team ID
    };

    const errors = [];
    
    if (invalidFixture.home_score < 0) {
      errors.push('Home score cannot be negative');
    }
    
    if (invalidFixture.away_score === null) {
      errors.push('Away score is required');
    }
    
    if (!invalidFixture.home_team_id) {
      errors.push('Home team ID is required');
    }
    
    if (!invalidFixture.away_team_id) {
      errors.push('Away team ID is required');
    }

    return {
      isValid: errors.length === 0,
      errors
    };
  }

  private validateInvalidTeamData(): any {
    const invalidTeam = {
      name: '', // Invalid: empty name
      points: -5, // Invalid: negative points
      __id__: null // Invalid: missing ID
    };

    const errors = [];
    
    if (!invalidTeam.name || invalidTeam.name.trim() === '') {
      errors.push('Team name is required');
    }
    
    if (invalidTeam.points < 0) {
      errors.push('Points cannot be negative');
    }
    
    if (!invalidTeam.__id__) {
      errors.push('Team ID is required');
    }

    return {
      isValid: errors.length === 0,
      errors
    };
  }

  private async simulateGoalAssignment(): Promise<any> {
    // Simulate goal assignment operation
    await new Promise(resolve => setTimeout(resolve, Math.random() * 100));
    return { operation: 'goal_assignment', status: 'completed' };
  }

  private async simulateCardCreation(): Promise<any> {
    // Simulate card creation operation
    await new Promise(resolve => setTimeout(resolve, Math.random() * 100));
    return { operation: 'card_creation', status: 'completed' };
  }

  private async simulateScoreUpdate(): Promise<any> {
    // Simulate score update operation
    await new Promise(resolve => setTimeout(resolve, Math.random() * 100));
    return { operation: 'score_update', status: 'completed' };
  }

  private async simulatePlayerTimeUpdate(): Promise<any> {
    // Simulate player time update operation
    await new Promise(resolve => setTimeout(resolve, Math.random() * 100));
    return { operation: 'player_time_update', status: 'completed' };
  }

  private async testStateRecovery(): Promise<any> {
    // Test state recovery after simulated error
    const initialState = { score: 0, players: [] };
    
    try {
      // Simulate operation that fails
      throw new Error('Simulated error');
    } catch (error) {
      // Test recovery
      const recoveredState = { ...initialState };
      return { 
        recovered: true, 
        state: recoveredState,
        message: 'State successfully recovered after error'
      };
    }
  }

  private async testDataRollback(): Promise<any> {
    // Test data rollback capabilities
    const transactionSteps = [
      { step: 1, action: 'create_player', success: true },
      { step: 2, action: 'assign_team', success: true },
      { step: 3, action: 'update_stats', success: false } // Simulate failure
    ];

    const failedStep = transactionSteps.find(step => !step.success);
    
    if (failedStep) {
      // Simulate rollback
      const rollbackSteps = transactionSteps
        .filter(step => step.step < failedStep.step)
        .reverse();
      
      return {
        rollbackRequired: true,
        failedAt: failedStep.step,
        rollbackSteps: rollbackSteps.length,
        message: `Rollback successful for ${rollbackSteps.length} operations`
      };
    }

    return { rollbackRequired: false, message: 'No rollback needed' };
  }

  private async testRetryMechanism(): Promise<any> {
    // Test retry mechanism
    let attempts = 0;
    const maxAttempts = 3;

    const operation = async (): Promise<any> => {
      attempts++;
      if (attempts < 3) {
        throw new Error(`Attempt ${attempts} failed`);
      }
      return { success: true, attempts };
    };

    try {
      const result = await this.retryOperation(operation, maxAttempts);
      return {
        success: true,
        totalAttempts: attempts,
        result,
        message: `Operation succeeded after ${attempts} attempts`
      };
    } catch (error) {
      return {
        success: false,
        totalAttempts: attempts,
        error: error instanceof Error ? error.message : 'Unknown error',
        message: `Operation failed after ${attempts} attempts`
      };
    }
  }

  private async retryOperation(operation: () => Promise<any>, maxAttempts: number): Promise<any> {
    let lastError;
    
    for (let attempt = 1; attempt <= maxAttempts; attempt++) {
      try {
        return await operation();
      } catch (error) {
        lastError = error;
        if (attempt === maxAttempts) {
          throw lastError;
        }
        // Wait before retry
        await new Promise(resolve => setTimeout(resolve, 50 * attempt));
      }
    }
    
    throw lastError;
  }
}
